<?xml version="1.0" encoding="utf-8"?>
<!-- This URDF was automatically created by SolidWorks to URDF Exporter! Originally created by Stephen Brawner (brawner@gmail.com) 
     Commit Version: 1.5.1-0-g916b5db  Build Version: 1.5.7152.31018
     For more information, please see http://wiki.ros.org/sw_urdf_exporter -->
<robot
  name="fr16-V5.0.SLDASM">
  <link
    name="base_link">
    <inertial>
      <origin
        xyz="-0.00037779 0.035824 0.00035123"
        rpy="0 0 0" />
      <mass
        value="0.73773" />
      <inertia
        ixx="0.0026261"
        ixy="-8.5597E-06"
        ixz="-1.1085E-05"
        iyy="0.0044464"
        iyz="8.0719E-06"
        izz="0.0026257" />
    </inertial>
    <visual>
      <origin
        xyz="0 0 0"
        rpy="0 0 0" />
      <geometry>
        <mesh
          filename="../meshes/fr16/visual/base_link.dae" />
      </geometry>
      <material
        name="">
        <color
          rgba="0.79216 0.81961 0.93333 1" />
      </material>
    </visual>
    <collision>
      <origin
        xyz="0 0 0"
        rpy="0 0 0" />
      <geometry>
        <mesh
          filename="../meshes/fr16/collision/base_link.STL" />
      </geometry>
    </collision>
  </link>
  <link
    name="shoulder_Link">
    <inertial>
      <origin
        xyz="-1.0816E-07 -0.13473 -0.0047771"
        rpy="0 0 0" />
      <mass
        value="3.8977" />
      <inertia
        ixx="0.018741"
        ixy="5.0033E-08"
        ixz="9.2604E-08"
        iyy="0.012373"
        iyz="1.6387E-05"
        izz="0.018267" />
    </inertial>
    <visual>
      <origin
        xyz="0 0 0"
        rpy="0 3.14159 0" />
      <geometry>
        <mesh
          filename="../meshes/fr16/visual/shoulder_Link.dae" />
      </geometry>
      <material
        name="">
        <color
          rgba="0.79216 0.81961 0.93333 1" />
      </material>
    </visual>
    <collision>
      <origin
        xyz="0 0 0"
        rpy="0 0 0" />
      <geometry>
        <mesh
          filename="../meshes/fr16/collision/shoulder_Link.STL" />
      </geometry>
    </collision>
  </link>
  <joint
    name="j1"
    type="revolute">
    <origin
      xyz="0 0 0.045908"
      rpy="-1.5708 3.14159 3.14159" />
    <parent
      link="base_link" />
    <child
      link="shoulder_Link" />
    <axis
      xyz="0 1 0" />
    <limit
      lower="-3.0543261"
      upper="3.0543261"
      effort="150"
      velocity="3.15" />
    <calibration
      rising="0"
      falling="0" />
    <dynamics
      damping="0"
      friction="0" />
    <safety_controller
      soft_upper="0"
      soft_lower="0"
      k_position="0"
      k_velocity="0" />
  </joint>
  <link
    name="upperarm_Link">
    <inertial>
      <origin
        xyz="-1.2243E-07 0.28754 -0.13462"
        rpy="0 0 0" />
      <mass
        value="11.568" />
      <inertia
        ixx="0.18366"
        ixy="-1.1858E-08"
        ixz="8.4371E-08"
        iyy="0.03371"
        iyz="-8.597E-06"
        izz="0.17531" />
    </inertial>
    <visual>
      <origin
        xyz="0 0 0.1"
        rpy="0 3.14159 0" />
      <geometry>
        <mesh
          filename="../meshes/fr16/visual/upperarm_Link.dae" />
      </geometry>
      <material
        name="">
        <color
          rgba="0.79216 0.81961 0.93333 1" />
      </material>
    </visual>
    <collision>
      <origin
        xyz="0 0 0"
        rpy="0 0 0" />
      <geometry>
        <mesh
          filename="../meshes/fr16/collision/upperarm_Link.STL" />
      </geometry>
    </collision>
  </link>
  <joint
    name="j2"
    type="revolute">
    <origin
      xyz="0 0.134 -0.05"
      rpy="0 0 1.570793" />
    <parent
      link="shoulder_Link" />
    <child
      link="upperarm_Link" />
    <axis
      xyz="0 0 1" />
    <limit
      lower="-4.6251"
      upper="1.4835"
      effort="150"
      velocity="3.15" />
    <calibration
      rising="0"
      falling="0" />
    <dynamics
      damping="0"
      friction="0" />
    <safety_controller
      soft_upper="0"
      soft_lower="0"
      k_position="0"
      k_velocity="0" />
  </joint>
  <link
    name="forearm_Link">
    <inertial>
      <origin
        xyz="-7.3696E-07 0.42863 0.0061272"
        rpy="0 0 0" />
      <mass
        value="1.5774" />
      <inertia
        ixx="0.012832"
        ixy="-7.5164E-09"
        ixz="2.0819E-10"
        iyy="0.0031275"
        iyz="-8.569E-05"
        izz="0.01198" />
    </inertial>
    <visual>
      <origin
        xyz="0 0 0"
        rpy="0 3.14159 0" />
      <geometry>
        <mesh
          filename="../meshes/fr16/visual/forearm_Link.dae" />
      </geometry>
      <material
        name="">
        <color
          rgba="0.79216 0.81961 0.93333 1" />
      </material>
    </visual>
    <collision>
      <origin
        xyz="0 0 0"
        rpy="0 0 0" />
      <geometry>
        <mesh
          filename="../meshes/fr16/collision/forearm_Link.STL" />
      </geometry>
    </collision>
  </link>
  <joint
    name="j3"
    type="revolute">
    <origin
      xyz="0 0.52 0.101"
      rpy="0 0 0" />
    <parent
      link="upperarm_Link" />
    <child
      link="forearm_Link" />
    <axis
      xyz="0 0 1" />
    <limit
      lower="-2.8274"
      upper="2.8274"
      effort="150"
      velocity="3.15" />
    <calibration
      rising="0"
      falling="0" />
    <dynamics
      damping="0"
      friction="0" />
    <safety_controller
      soft_upper="0"
      soft_lower="0"
      k_position="0"
      k_velocity="0" />
  </joint>
  <link
    name="wrist1_Link">
    <inertial>
      <origin
        xyz="1.119E-07 -0.0030015 0.074852"
        rpy="0 0 0" />
      <mass
        value="1.1074" />
      <inertia
        ixx="0.0019683"
        ixy="2.6898E-08"
        ixz="-6.9297E-09"
        iyy="0.0011013"
        iyz="3.8797E-06"
        izz="0.0020283" />
    </inertial>
    <visual>
      <origin
        xyz="0 0 0"
        rpy="3.14159 0 3.14159" />
      <geometry>
        <mesh
          filename="../meshes/fr16/visual/wrist1_Link.dae" />
      </geometry>
      <material
        name="">
        <color
          rgba="0.79216 0.81961 0.93333 1" />
      </material>
    </visual>
    <collision>
      <origin
        xyz="0 0 0"
        rpy="0 0 0" />
      <geometry>
        <mesh
          filename="../meshes/fr16/collision/wrist1_Link.STL" />
      </geometry>
    </collision>
  </link>
  <joint
    name="j4"
    type="revolute">
    <origin
      xyz="0 0.4 0.054"
      rpy="0 0 1.570793" />
    <parent
      link="forearm_Link" />
    <child
      link="wrist1_Link" />
    <axis
      xyz="0 0 1" />
    <limit
      lower="-4.6251"
      upper="1.4835"
      effort="28"
      velocity="3.2" />
    <calibration
      rising="0"
      falling="0" />
    <dynamics
      damping="0"
      friction="0" />
    <safety_controller
      soft_upper="0"
      soft_lower="0"
      k_position="0"
      k_velocity="0" />
  </joint>
  <link
    name="wrist2_Link">
    <inertial>
      <origin
        xyz="-0.058347 0.0037159 -0.0044844"
        rpy="0 0 0" />
      <mass
        value="0.89805" />
      <inertia
        ixx="0.0018083"
        ixy="3.8829E-06"
        ixz="-2.3592E-06"
        iyy="0.00097125"
        iyz="3.0557E-07"
        izz="0.0018386" />
    </inertial>
    <visual>
      <origin
        xyz="-0.115 0 0"
        rpy="3.14159 -1.5708 1.5708" />
      <geometry>
        <mesh
          filename="../meshes/fr16/visual/wrist2_Link.dae" />
      </geometry>
      <material
        name="">
        <color
          rgba="0.79216 0.81961 0.93333 1" />
      </material>
    </visual>
    <collision>
      <origin
        xyz="0 0 0"
        rpy="0 0 0" />
      <geometry>
        <mesh
          filename="../meshes/fr16/collision/wrist2_Link.STL" />
      </geometry>
    </collision>
  </link>
  <joint
    name="j5"
    type="revolute">
    <origin
      xyz="0 0.174 0.0895"
      rpy="-1.5708 0 1.5708" />
    <parent
      link="wrist1_Link" />
    <child
      link="wrist2_Link" />
    <axis
      xyz="1 0 0" />
    <limit
      lower="-3.0543"
      upper="3.0543"
      effort="28"
      velocity="3.2" />
    <calibration
      rising="0"
      falling="0" />
    <dynamics
      damping="0"
      friction="0" />
    <safety_controller
      soft_upper="0"
      soft_lower="0"
      k_position="0"
      k_velocity="0" />
  </joint>
  <link
    name="wrist3_Link">
    <inertial>
      <origin
        xyz="-1.8098E-05 0.022586 -2.1629E-05"
        rpy="0 0 0" />
      <mass
        value="0.24186" />
      <inertia
        ixx="0.00015143"
        ixy="9.9865E-08"
        ixz="7.787E-08"
        iyy="0.00024022"
        iyz="6.6716E-08"
        izz="0.00015134" />
    </inertial>
    <visual>
      <origin
        xyz="0 0 0"
        rpy="0 0 0" />
      <geometry>
        <mesh
          filename="../meshes/fr16/visual/wrist3_Link.dae" />
      </geometry>
      <material
        name="">
        <color
          rgba="0.79216 0.81961 0.93333 1" />
      </material>
    </visual>
    <collision>
      <origin
        xyz="0 0 0"
        rpy="0 0 0" />
      <geometry>
        <mesh
          filename="../meshes/fr16/collision/wrist3_Link.STL" />
      </geometry>
    </collision>
  </link>
  <joint
    name="j6"
    type="revolute">
    <origin
      xyz="-0.061 -0.06 -0"
      rpy="-3.1416 2.54 0" />
    <parent
      link="wrist2_Link" />
    <child
      link="wrist3_Link" />
    <axis
      xyz="0 1 0" />
    <limit
      lower="-3.0543"
      upper="3.0543"
      effort="28"
      velocity="3.2" />
    <calibration
      rising="0"
      falling="0" />
    <dynamics
      damping="0"
      friction="0" />
    <safety_controller
      soft_upper="0"
      soft_lower="0"
      k_position="0"
      k_velocity="0" />
  </joint>
  <joint
    name="tool"
    type="fixed">
    <origin
      xyz="0 0.05 0"
      rpy="-1.570796 -0.610865 0" />
    <parent
      link="wrist3_Link" />
    <child
      link="gripper_Link" />
    <axis
      xyz="0 0 1" />
    <limit
      lower="-3.0543"
      upper="3.0543"
      effort="28"
      velocity="3.2" />
    <calibration
      rising="0"
      falling="0" />
    <dynamics
      damping="0"
      friction="0" />
    <safety_controller
      soft_upper="0"
      soft_lower="0"
      k_position="0"
      k_velocity="0" />
  </joint>
  <!-- <link
    name="gripper_Link">
    <inertial>
      <origin
        xyz="0 0.05 0"
        rpy="-1.570796 -0.785398 0" />
      <mass
        value="0.52527" />
      <inertia
        ixx="0.00027801"
        ixy="-3.5346E-07"
        ixz="-1.7431E-07"
        iyy="0.00027736"
        iyz="-7.5888E-08"
        izz="0.00041582" />
    </inertial>
    <visual>
      <origin
        xyz="0 0 0"
        rpy="0 0 0" />
      <geometry>
        <mesh
          filename="../tool/gripper.dae" />
      </geometry>
      <material
        name="">
        <color
          rgba="0.89804 0.91765 0.92941 1" />
      </material>
    </visual>
    <collision>
      <origin
        xyz="0 0 0"
        rpy="0 0 0" />
      <geometry>
        <mesh
          filename="../tool/gripper.STL" />
      </geometry>
    </collision>
  </link> -->
</robot>