<?xml version="1.0" encoding="utf-8"?>
<!-- This URDF was automatically created by SolidWorks to URDF Exporter! Originally created by Stephen Brawner (brawner@gmail.com) 
     Commit Version: 1.5.1-0-g916b5db  Build Version: 1.5.7152.31018
     For more information, please see http://wiki.ros.org/sw_urdf_exporter -->
<robot
  name="FR10YD">
  <link
    name="base_link">
    <inertial>
      <origin
        xyz="-0.00037778 -0.00035367 0.035825"
        rpy="0 0 0" />
      <mass
        value="0.73775" />
      <inertia
        ixx="0.0026263"
        ixy="1.1085E-05"
        ixz="-8.5601E-06"
        iyy="0.0026258"
        iyz="-7.9868E-06"
        izz="0.0044466" />
    </inertial>
    <visual>
      <origin
        xyz="0 0 0"
        rpy="0 0 0" />
      <geometry>
        <mesh
          filename="../meshes/FR10YD/visual/base_link.dae" />
      </geometry>
      <material
        name="">
        <color
          rgba="1 1 1 1" />
      </material>
    </visual>
    <collision>
      <origin
        xyz="0 0 0"
        rpy="0 0 0" />
      <geometry>
        <mesh
          filename="../meshes/FR10YD/collision/base_link.STL" />
      </geometry>
    </collision>
  </link>
  <link
    name="j1_Link">
    <inertial>
      <origin
        xyz="3.389E-09 -0.0079713 0.17311"
        rpy="0 0 0" />
      <mass
        value="9.8122" />
      <inertia
        ixx="0.041746"
        ixy="-1.8666E-07"
        ixz="-2.3424E-07"
        iyy="0.039088"
        iyz="0.00068462"
        izz="0.031895" />
    </inertial>
    <visual>
      <origin
        xyz="0 0 0"
        rpy="0 0 0" />
      <geometry>
        <mesh
          filename="../meshes/FR10YD/visual/j1_Link.dae" />
      </geometry>
      <material
        name="">
        <color
          rgba="0.79216 0.81961 0.93333 1" />
      </material>
    </visual>
    <collision>
      <origin
        xyz="0 0 0"
        rpy="0 0 0" />
      <geometry>
        <mesh
          filename="../meshes/FR10YD/collision/j1_Link.STL" />
      </geometry>
    </collision>
  </link>
  <joint
    name="j1"
    type="revolute">
    <origin
      xyz="0 0 0"
      rpy="0 0 0" />
    <parent
      link="base_link" />
    <child
      link="j1_Link" />
    <axis
      xyz="0 0 1" />
    <limit
      lower="-3.0543"
      upper="3.0543"
      effort="150"
      velocity="3.15" />
    <calibration
      rising="0"
      falling="0" />
    <dynamics
      damping="0"
      friction="0" />
    <safety_controller
      soft_upper="0"
      soft_lower="0"
      k_position="0"
      k_velocity="0" />
  </joint>
  <link
    name="j2_Link">
    <inertial>
      <origin
        xyz="-0.2849 -1.1293E-06 0.18379"
        rpy="0 0 0" />
      <mass
        value="30.183" />
      <inertia
        ixx="0.079811"
        ixy="-5.1382E-06"
        ixz="0.0014657"
        iyy="0.39766"
        iyz="9.6953E-07"
        izz="0.38305" />
    </inertial>
    <visual>
      <origin
        xyz="0 0 0"
        rpy="0 0 0" />
      <geometry>
        <mesh
          filename="../meshes/FR10YD/visual/j2_Link.dae" />
      </geometry>
      <material
        name="">
        <color
          rgba="1 1 1 1" />
      </material>
    </visual>
    <collision>
      <origin
        xyz="0 0 0"
        rpy="0 0 0" />
      <geometry>
        <mesh
          filename="../meshes/FR10YD/collision/j2_Link.STL" />
      </geometry>
    </collision>
  </link>
  <joint
    name="j2"
    type="revolute">
    <origin
      xyz="0 0 0.18"
      rpy="1.5708 0 0" />
    <parent
      link="j1_Link" />
    <child
      link="j2_Link" />
    <axis
      xyz="0 0 1" />
    <limit
      lower="-4.6251"
      upper="1.4835"
      effort="150"
      velocity="3.15" />
    <calibration
      rising="0"
      falling="0" />
    <dynamics
      damping="0"
      friction="0" />
    <safety_controller
      soft_upper="0"
      soft_lower="0"
      k_position="0"
      k_velocity="0" />
  </joint>
  <link
    name="j3_Link">
    <inertial>
      <origin
        xyz="-0.29261 -8.3716E-07 0.32084"
        rpy="0 0 0" />
      <mass
        value="12.661" />
      <inertia
        ixx="0.015624"
        ixy="3.4727E-06"
        ixz="0.011643"
        iyy="0.53513"
        iyz="-8.4915E-07"
        izz="0.53335" />
    </inertial>
    <visual>
      <origin
        xyz="0 0 0"
        rpy="0 0 0" />
      <geometry>
        <mesh
          filename="../meshes/FR10YD/visual/j3_Link.dae" />
      </geometry>
      <material
        name="">
        <color
          rgba="0.79216 0.81961 0.93333 1" />
      </material>
    </visual>
    <collision>
      <origin
        xyz="0 0 0"
        rpy="0 0 0" />
      <geometry>
        <mesh
          filename="../meshes/FR10YD/collision/j3_Link.STL" />
      </geometry>
    </collision>
  </link>
  <joint
    name="j3"
    type="revolute">
    <origin
      xyz="-0.7 0 0"
      rpy="0 0 0" />
    <parent
      link="j2_Link" />
    <child
      link="j3_Link" />
    <axis
      xyz="0 0 1" />
    <limit
      lower="-2.8274"
      upper="2.8274"
      effort="150"
      velocity="3.15" />
    <calibration
      rising="0"
      falling="0" />
    <dynamics
      damping="0"
      friction="0" />
    <safety_controller
      soft_upper="0"
      soft_lower="0"
      k_position="0"
      k_velocity="0" />
  </joint>
  <link
    name="j4_Link">
    <inertial>
      <origin
        xyz="-2.1757E-07 -0.0029989 0.21667"
        rpy="0 0 0" />
      <mass
        value="2.2101" />
      <inertia
        ixx="0.0036372"
        ixy="2.4674E-09"
        ixz="7.6619E-09"
        iyy="0.0026454"
        iyz="-3.558E-05"
        izz="0.003368" />
    </inertial>
    <visual>
      <origin
        xyz="0 0 0"
        rpy="0 0 0" />
      <geometry>
        <mesh
          filename="../meshes/FR10YD/visual/j4_Link.dae" />
      </geometry>
      <material
        name="">
        <color
          rgba="1 1 1 1" />
      </material>
    </visual>
    <collision>
      <origin
        xyz="0 0 0"
        rpy="0 0 0" />
      <geometry>
        <mesh
          filename="../meshes/FR10YD/collision/j4_Link.STL" />
      </geometry>
    </collision>
  </link>
  <joint
    name="j4"
    type="revolute">
    <origin
      xyz="-0.586 0 0"
      rpy="0 0 0" />
    <parent
      link="j3_Link" />
    <child
      link="j4_Link" />
    <axis
      xyz="0 0 1" />
    <limit
      lower="-4.6251"
      upper="1.4835"
      effort="28"
      velocity="3.2" />
    <calibration
      rising="0"
      falling="0" />
    <dynamics
      damping="0"
      friction="0" />
    <safety_controller
      soft_upper="0"
      soft_lower="0"
      k_position="0"
      k_velocity="0" />
  </joint>
  <link
    name="j5_Link">
    <inertial>
      <origin
        xyz="-2.1757E-07 0.0029989 0.10863"
        rpy="0 0 0" />
      <mass
        value="2.2101" />
      <inertia
        ixx="0.0036372"
        ixy="-2.4674E-09"
        ixz="-7.6619E-09"
        iyy="0.0026454"
        iyz="-3.558E-05"
        izz="0.003368" />
    </inertial>
    <visual>
      <origin
        xyz="0 0 0"
        rpy="0 0 0" />
      <geometry>
        <mesh
          filename="../meshes/FR10YD/visual/j5_Link.dae" />
      </geometry>
      <material
        name="">
        <color
          rgba="1 1 1 1" />
      </material>
    </visual>
    <collision>
      <origin
        xyz="0 0 0"
        rpy="0 0 0" />
      <geometry>
        <mesh
          filename="../meshes/FR10YD/collision/j5_Link.STL" />
      </geometry>
    </collision>
  </link>
  <joint
    name="j5"
    type="revolute">
    <origin
      xyz="0 0 0.2113"
      rpy="1.5708 0 0" />
    <parent
      link="j4_Link" />
    <child
      link="j5_Link" />
    <axis
      xyz="0 0 1" />
    <limit
      lower="0"
      upper="6.265732"
      effort="28"
      velocity="3.2" />
    <calibration
      rising="0"
      falling="0" />
    <dynamics
      damping="0"
      friction="0" />
    <safety_controller
      soft_upper="0"
      soft_lower="0"
      k_position="0"
      k_velocity="0" />
  </joint>
  <link
    name="j6_Link">
    <inertial>
      <origin
        xyz="8.5143E-06 3.2117E-05 -0.023532"
        rpy="0 0 0" />
      <mass
        value="0.20197" />
      <inertia
        ixx="0.00011214"
        ixy="5.6037E-10"
        ixz="-5.3365E-09"
        iyy="0.00011226"
        iyz="-9.9343E-08"
        izz="0.00016839" />
    </inertial>
    <visual>
      <origin
        xyz="0 0 0"
        rpy="0 0 0" />
      <geometry>
        <mesh
          filename="../meshes/FR10YD/visual/j6_Link.dae" />
      </geometry>
      <material
        name="">
        <color
          rgba="1 1 1 1" />
      </material>
    </visual>
    <collision>
      <origin
        xyz="0 0 0"
        rpy="0 0 0" />
      <geometry>
        <mesh
          filename="../meshes/FR10YD/collision/j6_Link.STL" />
      </geometry>
    </collision>
  </link>
  <joint
    name="j6"
    type="revolute">
    <origin
      xyz="0 0.106 0.114"
      rpy="1.5708 0 -3.1416" />
    <parent
      link="j5_Link" />
    <child
      link="j6_Link" />
    <axis
      xyz="0 0 1" />
    <limit
      lower="-3.0543"
      upper="3.0543"
      effort="28"
      velocity="3.2" />
    <calibration
      rising="0"
      falling="0" />
    <dynamics
      damping="0"
      friction="0" />
    <safety_controller
      soft_upper="0"
      soft_lower="0"
      k_position="0"
      k_velocity="0" />
  </joint>
  <joint
    name="tool"
    type="fixed">
    <origin
      xyz="0 0 0"
      rpy="0 0 -1.570796" />
    <parent
      link="j6_Link" />
    <child
      link="gripper_Link" />
    <axis
      xyz="0 0 1" />
    <limit
      lower="-3.0543"
      upper="3.0543"
      effort="28"
      velocity="3.2" />
    <calibration
      rising="0"
      falling="0" />
    <dynamics
      damping="0"
      friction="0" />
    <safety_controller
      soft_upper="0"
      soft_lower="0"
      k_position="0"
      k_velocity="0" />
  </joint>
  <!-- <link
    name="gripper_Link">
    <inertial>
      <origin
        xyz="5.8427E-06 7.5807E-05 0.079126"
        rpy="0 0 0" />
      <mass
        value="0.52527" />
      <inertia
        ixx="0.00027801"
        ixy="-3.5346E-07"
        ixz="-1.7431E-07"
        iyy="0.00027736"
        iyz="-7.5888E-08"
        izz="0.00041582" />
    </inertial>
    <visual>
      <origin
        xyz="0 0 0"
        rpy="0 0 0" />
      <geometry>
        <mesh
          filename="../tool/gripper.dae" />
      </geometry>
      <material
        name="">
        <color
          rgba="0.89804 0.91765 0.92941 1" />
      </material>
    </visual>
    <collision>
      <origin
        xyz="0 0 0"
        rpy="0 0 0" />
      <geometry>
        <mesh
          filename="../tool/gripper.STL" />
      </geometry>
    </collision>
  </link> -->
</robot>