<?xml version="1.0" encoding="utf-8"?>
<!-- This URDF was automatically created by SolidWorks to URDF Exporter! Originally created by Stephen Brawner (brawner@gmail.com) 
     Commit Version: 1.5.1-0-g916b5db  Build Version: 1.5.7152.31018
     For more information, please see http://wiki.ros.org/sw_urdf_exporter -->
<robot
  name="fr16v6">
  <link
    name="base_link">
    <inertial>
      <origin
        xyz="-0.00017171 -0.00016075 0.041272"
        rpy="0 0 0" />
      <mass
        value="1.6231" />
      <inertia
        ixx="0.0039513"
        ixy="1.1032E-05"
        ixz="-1.0078E-05"
        iyy="0.0039509"
        iyz="-9.408E-06"
        izz="0.0063729" />
    </inertial>
    <visual>
      <origin
        xyz="0 0 0"
        rpy="0 0 0" />
      <geometry>
        <mesh
          filename="../meshes/fr16/visual-v6.0/base_link.DAE" />
      </geometry>
      <material
        name="">
        <color
          rgba="0.79216 0.81961 0.93333 1" />
      </material>
    </visual>
    <collision>
      <origin
        xyz="0 0 0"
        rpy="0 0 0" />
      <geometry>
        <mesh
          filename="../meshes/fr16/collision-v6.0/base_link.STL" />
      </geometry>
    </collision>
  </link>
  <link
    name="j1_Link">
    <inertial>
      <origin
        xyz="2.6949E-07 -0.0077161 0.17504"
        rpy="0 0 0" />
      <mass
        value="3.7152" />
      <inertia
        ixx="0.015538"
        ixy="-6.8007E-08"
        ixz="-8.8038E-08"
        iyy="0.014566"
        iyz="0.00023847"
        izz="0.012006" />
    </inertial>
    <visual>
      <origin
        xyz="0 0 0"
        rpy="0 0 0" />
      <geometry>
        <mesh
          filename="../meshes/fr16/visual-v6.0/j1_Link.DAE" />
      </geometry>
      <material
        name="">
        <color
          rgba="0.79216 0.81961 0.93333 1" />
      </material>
    </visual>
    <collision>
      <origin
        xyz="0 0 0"
        rpy="0 0 0" />
      <geometry>
        <mesh
          filename="../meshes/fr16/collision-v6.0/j1_Link.STL" />
      </geometry>
    </collision>
  </link>
  <joint
    name="j1"
    type="revolute">
    <origin
      xyz="0 0 0"
      rpy="0 0 0" />
    <parent
      link="base_link" />
    <child
      link="j1_Link" />
    <axis
      xyz="0 0 1" />
    <limit
      lower="-3.0543"
      upper="3.0543"
      effort="150"
      velocity="3.15" />
    <calibration
      rising="0"
      falling="0" />
    <dynamics
      damping="0"
      friction="0" />
    <safety_controller
      soft_upper="0"
      soft_lower="0"
      k_position="0"
      k_velocity="0" />
  </joint>
  <link
    name="j2_Link">
    <inertial>
      <origin
        xyz="-0.20845 -1.0388E-06 0.18245"
        rpy="0 0 0" />
      <mass
        value="9.4622" />
      <inertia
        ixx="0.025921"
        ixy="2.097E-07"
        ixz="0.0025747"
        iyy="0.37903"
        iyz="1.3969E-07"
        izz="0.37439" />
    </inertial>
    <visual>
      <origin
        xyz="0 0 0"
        rpy="0 0 0" />
      <geometry>
        <mesh
          filename="../meshes/fr16/visual-v6.0/j2_Link.DAE" />
      </geometry>
      <material
        name="">
        <color
          rgba="0.79216 0.81961 0.93333 1" />
      </material>
    </visual>
    <collision>
      <origin
        xyz="0 0 0"
        rpy="0 0 0" />
      <geometry>
        <mesh
          filename="../meshes/fr16/collision-v6.0/j2_Link.STL" />
      </geometry>
    </collision>
  </link>
  <joint
    name="j2"
    type="revolute">
    <origin
      xyz="0 0 0.18"
      rpy="1.5708 0 0" />
    <parent
      link="j1_Link" />
    <child
      link="j2_Link" />
    <axis
      xyz="0 0 1" />
    <limit
      lower="-4.6251"
      upper="1.4835"
      effort="150"
      velocity="3.15" />
    <calibration
      rising="0"
      falling="0" />
    <dynamics
      damping="0"
      friction="0" />
    <safety_controller
      soft_upper="0"
      soft_lower="0"
      k_position="0"
      k_velocity="0" />
  </joint>
  <link
    name="j3_Link">
    <inertial>
      <origin
        xyz="-0.23441 5.6569E-07 0.048131"
        rpy="0 0 0" />
      <mass
        value="2.9964" />
      <inertia
        ixx="0.003827"
        ixy="-1.6004E-07"
        ixz="-0.0011373"
        iyy="0.054019"
        iyz="-5.5129E-08"
        izz="0.053512" />
    </inertial>
    <visual>
      <origin
        xyz="0 0 0"
        rpy="0 0 0" />
      <geometry>
        <mesh
          filename="../meshes/fr16/visual-v6.0/j3_Link.DAE" />
      </geometry>
      <material
        name="">
        <color
          rgba="0.79216 0.81961 0.93333 1" />
      </material>
    </visual>
    <collision>
      <origin
        xyz="0 0 0"
        rpy="0 0 0" />
      <geometry>
        <mesh
          filename="../meshes/fr16/collision-v6.0/j3_Link.STL" />
      </geometry>
    </collision>
  </link>
  <joint
    name="j3"
    type="revolute">
    <origin
      xyz="-0.52 0 0"
      rpy="0 0 0" />
    <parent
      link="j2_Link" />
    <child
      link="j3_Link" />
    <axis
      xyz="0 0 1" />
    <limit
      lower="-2.8274"
      upper="2.8274"
      effort="150"
      velocity="3.15" />
    <calibration
      rising="0"
      falling="0" />
    <dynamics
      damping="0"
      friction="0" />
    <safety_controller
      soft_upper="0"
      soft_lower="0"
      k_position="0"
      k_velocity="0" />
  </joint>
  <link
    name="j4_Link">
    <inertial>
      <origin
        xyz="2.4949E-07 -0.002597 0.1549"
        rpy="0 0 0" />
      <mass
        value="2.1573" />
      <inertia
        ixx="0.0033086"
        ixy="1.2835E-08"
        ixz="6.0662E-08"
        iyy="0.0024933"
        iyz="3.9256E-05"
        izz="0.003143" />
    </inertial>
    <visual>
      <origin
        xyz="0 0 0"
        rpy="0 0 0" />
      <geometry>
        <mesh
          filename="../meshes/fr16/visual-v6.0/j4_Link.DAE" />
      </geometry>
      <material
        name="">
        <color
          rgba="0.79216 0.81961 0.93333 1" />
      </material>
    </visual>
    <collision>
      <origin
        xyz="0 0 0"
        rpy="0 0 0" />
      <geometry>
        <mesh
          filename="../meshes/fr16/collision-v6.0/j4_Link.STL" />
      </geometry>
    </collision>
  </link>
  <joint
    name="j4"
    type="revolute">
    <origin
      xyz="-0.4 0 0"
      rpy="0 0 0" />
    <parent
      link="j3_Link" />
    <child
      link="j4_Link" />
    <axis
      xyz="0 0 1" />
    <limit
      lower="-4.6251"
      upper="1.4835"
      effort="28"
      velocity="3.2" />
    <calibration
      rising="0"
      falling="0" />
    <dynamics
      damping="0"
      friction="0" />
    <safety_controller
      soft_upper="0"
      soft_lower="0"
      k_position="0"
      k_velocity="0" />
  </joint>
  <link
    name="j5_Link">
    <inertial>
      <origin
        xyz="-2.4949E-07 0.002597 0.1099"
        rpy="0 0 0" />
      <mass
        value="2.1573" />
      <inertia
        ixx="0.0033086"
        ixy="1.2835E-08"
        ixz="-6.0662E-08"
        iyy="0.0024933"
        iyz="-3.9256E-05"
        izz="0.003143" />
    </inertial>
    <visual>
      <origin
        xyz="0 0 0"
        rpy="0 0 0" />
      <geometry>
        <mesh
          filename="../meshes/fr16/visual-v6.0/j5_Link.DAE" />
      </geometry>
      <material
        name="">
        <color
          rgba="0.79216 0.81961 0.93333 1" />
      </material>
    </visual>
    <collision>
      <origin
        xyz="0 0 0"
        rpy="0 0 0" />
      <geometry>
        <mesh
          filename="../meshes/fr16/collision-v6.0/j5_Link.STL" />
      </geometry>
    </collision>
  </link>
  <joint
    name="j5"
    type="revolute">
    <origin
      xyz="0 0 0.159"
      rpy="1.5708 0 0" />
    <parent
      link="j4_Link" />
    <child
      link="j5_Link" />
    <axis
      xyz="0 0 1" />
    <limit
      lower="-3.0543"
      upper="3.0543"
      effort="28"
      velocity="3.2" />
    <calibration
      rising="0"
      falling="0" />
    <dynamics
      damping="0"
      friction="0" />
    <safety_controller
      soft_upper="0"
      soft_lower="0"
      k_position="0"
      k_velocity="0" />
  </joint>
  <link
    name="j6_Link">
    <inertial>
      <origin
        xyz="-8.7063E-06 -3.2122E-05 0.082426"
        rpy="0 0 0" />
      <mass
        value="0.20145" />
      <inertia
        ixx="0.0001117"
        ixy="9.1303E-11"
        ixz="6.3367E-09"
        iyy="0.00011182"
        iyz="9.9213E-08"
        izz="0.00016776" />
    </inertial>
    <visual>
      <origin
        xyz="0 0 0"
        rpy="0 0 0" />
      <geometry>
        <mesh
          filename="../meshes/fr16/visual-v6.0/j6_Link.DAE" />
      </geometry>
      <material
        name="">
        <color
          rgba="0.79216 0.81961 0.93333 1" />
      </material>
    </visual>
    <collision>
      <origin
        xyz="0 0 0"
        rpy="0 0 0" />
      <geometry>
        <mesh
          filename="../meshes/fr16/collision-v6.0/j6_Link.STL" />
      </geometry>
    </collision>
  </link>
  <joint
    name="j6"
    type="revolute">
    <origin
      xyz="0 0 0.114"
      rpy="-1.5708 0 0" />
    <parent
      link="j5_Link" />
    <child
      link="j6_Link" />
    <axis
      xyz="0 0 1" />
    <limit
      lower="-3.0543"
      upper="3.0543"
      effort="28"
      velocity="3.2" />
    <calibration
      rising="0"
      falling="0" />
    <dynamics
      damping="0"
      friction="0" />
    <safety_controller
      soft_upper="0"
      soft_lower="0"
      k_position="0"
      k_velocity="0" />
  </joint>
  <joint
    name="tool"
    type="fixed">
    <origin
      xyz="0 0 0.107"
      rpy="0 0 1.570796" />
    <parent
      link="j6_Link" />
    <child
      link="gripper_Link" />
    <axis
      xyz="0 0 1" />
    <limit
      lower="-3.0543"
      upper="3.0543"
      effort="28"
      velocity="3.2" />
    <calibration
      rising="0"
      falling="0" />
    <dynamics
      damping="0"
      friction="0" />
    <safety_controller
      soft_upper="0"
      soft_lower="0"
      k_position="0"
      k_velocity="0" />
  </joint>
  <!-- <link
    name="gripper_Link">
    <inertial>
      <origin
        xyz="5.8427E-06 7.5807E-05 0.079126"
        rpy="0 0 0" />
      <mass
        value="0.52527" />
      <inertia
        ixx="0.00027801"
        ixy="-3.5346E-07"
        ixz="-1.7431E-07"
        iyy="0.00027736"
        iyz="-7.5888E-08"
        izz="0.00041582" />
    </inertial>
    <visual>
      <origin
        xyz="0 0 0"
        rpy="0 0 0" />
      <geometry>
        <mesh
          filename="../tool/gripper.dae" />
      </geometry>
      <material
        name="">
        <color
          rgba="0.89804 0.91765 0.92941 1" />
      </material>
    </visual>
    <collision>
      <origin
        xyz="0 0 0"
        rpy="0 0 0" />
      <geometry>
        <mesh
          filename="../tool/gripper.STL" />
      </geometry>
    </collision>
  </link> -->
</robot>