<?xml version="1.0" encoding="utf-8"?>
<!-- This URDF was automatically created by SolidWorks to URDF Exporter! Originally created by Stephen Brawner (brawner@gmail.com) 
     Commit Version: 1.5.1-0-g916b5db  Build Version: 1.5.7152.31018
     For more information, please see http://wiki.ros.org/sw_urdf_exporter -->
<robot
  name="FR3MT">
  <link
    name="base_link">
    <inertial>
      <origin
        xyz="-1.5389E-05 0.0050006 0.035726"
        rpy="0 0 0" />
      <mass
        value="0.60007" />
      <inertia
        ixx="0.00077666"
        ixy="5.901E-07"
        ixz="4.3886E-07"
        iyy="0.00066312"
        iyz="-1.924E-05"
        izz="0.00080686" />
    </inertial>
    <visual>
      <origin
        xyz="0 0 0"
        rpy="0 0 0" />
      <geometry>
        <mesh
          filename="../meshes/FR3MT/visual/base_link.dae" />
      </geometry>
      <material
        name="">
        <color
          rgba="1 1 1 1" />
      </material>
    </visual>
    <collision>
      <origin
        xyz="0 0 0"
        rpy="0 0 0" />
      <geometry>
        <mesh
          filename="../meshes/FR3MT/collision/base_link.STL" />
      </geometry>
    </collision>
  </link>
  <link
    name="shoulder_Link">
    <inertial>
      <origin
        xyz="-1.7189E-07 -0.0044494 0.13907"
        rpy="0 0 0" />
      <mass
        value="1.59" />
      <inertia
        ixx="0.0011031"
        ixy="-2.2173E-08"
        ixz="-5.772E-09"
        iyy="0.001042"
        iyz="3.0347E-06"
        izz="0.00087179" />
    </inertial>
    <visual>
      <origin
        xyz="0 0 0"
        rpy="0 0 0" />
      <geometry>
        <mesh
          filename="../meshes/FR3MT/visual/shoulder_Link.dae" />
      </geometry>
      <material
        name="">
        <color
          rgba="1 1 1 1" />
      </material>
    </visual>
    <collision>
      <origin
        xyz="0 0 0"
        rpy="0 0 0" />
      <geometry>
        <mesh
          filename="../meshes/FR3MT/collision/shoulder_Link.STL" />
      </geometry>
    </collision>
  </link>
  <joint
    name="j1"
    type="revolute">
    <origin
      xyz="0 0 0"
      rpy="0 0 0" />
    <parent
      link="base_link" />
    <child
      link="shoulder_Link" />
    <axis
      xyz="0 0 1" />
    <limit
      lower="-3.0543"
      upper="3.0543"
      effort="150"
      velocity="3.15" />
    <calibration
      rising="0"
      falling="0" />
    <dynamics
      damping="0"
      friction="0" />
    <safety_controller
      soft_upper="0"
      soft_lower="0"
      k_position="0"
      k_velocity="0" />
  </joint>
  <link
    name="upperarm_Link">
    <inertial>
      <origin
        xyz="-0.13999 1.3167E-06 0.11244"
        rpy="0 0 0" />
      <mass
        value="3.41" />
      <inertia
        ixx="0.0027722"
        ixy="-2.1498E-08"
        ixz="3.3374E-06"
        iyy="0.033605"
        iyz="5.3384E-09"
        izz="0.03293" />
    </inertial>
    <visual>
      <origin
        xyz="0 0 0"
        rpy="0 0 0" />
      <geometry>
        <mesh
          filename="../meshes/FR3MT/visual/upperarm_Link.dae" />
      </geometry>
      <material
        name="">
        <color
          rgba="1 1 1 1" />
      </material>
    </visual>
    <collision>
      <origin
        xyz="0 0 0"
        rpy="0 0 0" />
      <geometry>
        <mesh
          filename="../meshes/FR3MT/collision/upperarm_Link.STL" />
      </geometry>
    </collision>
  </link>
  <joint
    name="j2"
    type="revolute">
    <origin
      xyz="0 0 0.14"
      rpy="1.5708 0 0" />
    <parent
      link="shoulder_Link" />
    <child
      link="upperarm_Link" />
    <axis
      xyz="0 0 1" />
    <limit
      lower="-4.6251"
      upper="1.4835"
      effort="150"
      velocity="3.15" />
    <calibration
      rising="0"
      falling="0" />
    <dynamics
      damping="0"
      friction="0" />
    <safety_controller
      soft_upper="0"
      soft_lower="0"
      k_position="0"
      k_velocity="0" />
  </joint>
  <link
    name="forearm_Link">
    <inertial>
      <origin
        xyz="-0.12848 3.4608E-07 0.0060745"
        rpy="0 0 0" />
      <mass
        value="1.68" />
      <inertia
        ixx="0.0014009"
        ixy="2.6983E-09"
        ixz="-0.0008874"
        iyy="0.01524"
        iyz="-2.5444E-09"
        izz="0.014953" />
    </inertial>
    <visual>
      <origin
        xyz="0 0 0"
        rpy="0 0 0" />
      <geometry>
        <mesh
          filename="../meshes/FR3MT/visual/forearm_Link.dae" />
      </geometry>
      <material
        name="">
        <color
          rgba="1 1 1 1" />
      </material>
    </visual>
    <collision>
      <origin
        xyz="0 0 0"
        rpy="0 0 0" />
      <geometry>
        <mesh
          filename="../meshes/FR3MT/collision/forearm_Link.STL" />
      </geometry>
    </collision>
  </link>
  <joint
    name="j3"
    type="revolute">
    <origin
      xyz="-0.28 0 3.3292E-05"
      rpy="0 0 0" />
    <parent
      link="upperarm_Link" />
    <child
      link="forearm_Link" />
    <axis
      xyz="0 0 1" />
    <limit
      lower="-2.618"
      upper="2.618"
      effort="150"
      velocity="3.15" />
    <calibration
      rising="0"
      falling="0" />
    <dynamics
      damping="0"
      friction="0" />
    <safety_controller
      soft_upper="0"
      soft_lower="0"
      k_position="0"
      k_velocity="0" />
  </joint>
  <link
    name="wrist1_Link">
    <inertial>
      <origin
        xyz="1.2181E-05 -0.0014491 0.097998"
        rpy="0 0 0" />
      <mass
        value="1.14" />
      <inertia
        ixx="0.00067888"
        ixy="3.1604E-09"
        ixz="2.1764E-08"
        iyy="0.00050724"
        iyz="3.1632E-06"
        izz="0.00064083" />
    </inertial>
    <visual>
      <origin
        xyz="0 0 0"
        rpy="0 0 0" />
      <geometry>
        <mesh
          filename="../meshes/FR3MT/visual/wrist1_Link.dae" />
      </geometry>
      <material
        name="">
        <color
          rgba="1 1 1 1" />
      </material>
    </visual>
    <collision>
      <origin
        xyz="0 0 0"
        rpy="0 0 0" />
      <geometry>
        <mesh
          filename="../meshes/FR3MT/collision/wrist1_Link.STL" />
      </geometry>
    </collision>
  </link>
  <joint
    name="j4"
    type="revolute">
    <origin
      xyz="-0.24 0 2.7002E-05"
      rpy="0 0 0" />
    <parent
      link="forearm_Link" />
    <child
      link="wrist1_Link" />
    <axis
      xyz="0 0 1" />
    <limit
      lower="-4.6251"
      upper="1.4835"
      effort="28"
      velocity="3.2" />
    <calibration
      rising="0"
      falling="0" />
    <dynamics
      damping="0"
      friction="0" />
    <safety_controller
      soft_upper="0"
      soft_lower="0"
      k_position="0"
      k_velocity="0" />
  </joint>
  <link
    name="wrist2_Link">
    <inertial>
      <origin
        xyz="-2.3064E-07 0.0014482 0.097997"
        rpy="0 0 0" />
      <mass
        value="1.14" />
      <inertia
        ixx="0.00067891"
        ixy="-1.7159E-08"
        ixz="-1.7461E-08"
        iyy="0.00050725"
        iyz="-3.1632E-06"
        izz="0.00064085" />
    </inertial>
    <visual>
      <origin
        xyz="0 0 0"
        rpy="0 0 0" />
      <geometry>
        <mesh
          filename="../meshes/FR3MT/visual/wrist2_Link.dae" />
      </geometry>
      <material
        name="">
        <color
          rgba="1 1 1 1" />
      </material>
    </visual>
    <collision>
      <origin
        xyz="0 0 0"
        rpy="0 0 0" />
      <geometry>
        <mesh
          filename="../meshes/FR3MT/collision/wrist2_Link.STL" />
      </geometry>
    </collision>
  </link>
  <joint
    name="j5"
    type="revolute">
    <origin
      xyz="1.1476E-05 0 0.102"
      rpy="1.5708 0 0" />
    <parent
      link="wrist1_Link" />
    <child
      link="wrist2_Link" />
    <axis
      xyz="0 0 1" />
    <limit
      lower="0"
      upper="6.2657"
      effort="28"
      velocity="3.2" />
    <calibration
      rising="0"
      falling="0" />
    <dynamics
      damping="0"
      friction="0" />
    <safety_controller
      soft_upper="0"
      soft_lower="0"
      k_position="0"
      k_velocity="0" />
  </joint>
  <link
    name="wrist3_Link">
    <inertial>
      <origin
        xyz="-2.6225E-05 -4.8511E-05 -0.02336"
        rpy="0 0 0" />
      <mass
        value="0.35" />
      <inertia
        ixx="0.00010707"
        ixy="2.4911E-10"
        ixz="2.1498E-08"
        iyy="0.00010719"
        iyz="1.0269E-07"
        izz="0.00015855" />
    </inertial>
    <visual>
      <origin
        xyz="0 0 0"
        rpy="0 0 0" />
      <geometry>
        <mesh
          filename="../meshes/FR3MT/visual/wrist3_Link.dae" />
      </geometry>
      <material
        name="">
        <color
          rgba="1 1 1 1" />
      </material>
    </visual>
    <collision>
      <origin
        xyz="0 0 0"
        rpy="0 0 0" />
      <geometry>
        <mesh
          filename="../meshes/FR3MT/collision/wrist3_Link.STL" />
      </geometry>
    </collision>
  </link>
  <joint
    name="j6"
    type="revolute">
    <origin
      xyz="1.1255E-05 0.1 0.102"
      rpy="-1.5708 0 0" />
    <parent
      link="wrist2_Link" />
    <child
      link="wrist3_Link" />
    <axis
      xyz="0 0 1" />
    <limit
      lower="-3.0543"
      upper="3.0543"
      effort="28"
      velocity="3.2" />
    <calibration
      rising="0"
      falling="0" />
    <dynamics
      damping="0"
      friction="0" />
    <safety_controller
      soft_upper="0"
      soft_lower="0"
      k_position="0"
      k_velocity="0" />
  </joint>
  <joint
    name="tool"
    type="fixed">
    <origin
      xyz="0 0 0"
      rpy="0 0 1.570796" />
    <parent
      link="wrist3_Link" />
    <child
      link="gripper_Link" />
    <axis
      xyz="0 0 1" />
    <limit
      lower="-3.0543261"
      upper="3.0543261"
      effort="28"
      velocity="3.2" />
    <calibration
      rising="0"
      falling="0" />
    <dynamics
      damping="0"
      friction="0" />
    <safety_controller
      soft_upper="0"
      soft_lower="0"
      k_position="0"
      k_velocity="0" />
  </joint>
  <!-- <link
    name="gripper_Link">
    <inertial>
      <origin
        xyz="5.8427E-06 7.5807E-05 0.079126"
        rpy="0 0 0" />
      <mass
        value="0.52527" />
      <inertia
        ixx="0.00027801"
        ixy="-3.5346E-07"
        ixz="-1.7431E-07"
        iyy="0.00027736"
        iyz="-7.5888E-08"
        izz="0.00041582" />
    </inertial>
    <visual>
      <origin
        xyz="0 0 0"
        rpy="0 0 0" />
      <geometry>
        <mesh
          filename="../tool/gripper.dae" />
      </geometry>
      <material
        name="">
        <color
          rgba="0.89804 0.91765 0.92941 1" />
      </material>
    </visual>
    <collision>
      <origin
        xyz="0 0 0"
        rpy="0 0 0" />
      <geometry>
        <mesh
          filename="../tool/gripper.STL" />
      </geometry>
    </collision>
  </link> -->
</robot>