<?xml version="1.0" encoding="utf-8"?>
<!-- This URDF was automatically created by SolidWorks to URDF Exporter! Originally created by Stephen Brawner (brawner@gmail.com) 
     Commit Version: 1.5.1-0-g916b5db  Build Version: 1.5.7152.31018
     For more information, please see http://wiki.ros.org/sw_urdf_exporter -->
<robot
  name="fr30v6">
  <link
    name="base_link">
    <inertial>
      <origin
        xyz="-2.164E-05 -6.0529E-05 0.043457"
        rpy="0 0 0" />
      <mass
        value="9.2502" />
      <inertia
        ixx="0.034499"
        ixy="1.668E-05"
        ixz="-7.4694E-06"
        iyy="0.034518"
        iyz="-2.0864E-05"
        izz="0.05496" />
    </inertial>
    <visual>
      <origin
        xyz="0 0 0"
        rpy="0 0 0" />
      <geometry>
        <mesh
          filename="../meshes/fr30/visual/base_link.dae" />
      </geometry>
      <material
        name="">
        <color
          rgba="1 1 1 1" />
      </material>
    </visual>
    <collision>
      <origin
        xyz="0 0 0"
        rpy="0 0 0" />
      <geometry>
        <mesh
          filename="../meshes/fr30/collision/base_link.STL" />
      </geometry>
    </collision>
  </link>
  <link
    name="shoulder_Link">
    <inertial>
      <origin
        xyz="-4.518E-06 -0.010267 0.213"
        rpy="0 0 0" />
      <mass
        value="20.64" />
      <inertia
        ixx="0.12521"
        ixy="-1.1623E-05"
        ixz="1.7646E-06"
        iyy="0.11672"
        iyz="0.0010853"
        izz="0.10221" />
    </inertial>
    <visual>
      <origin
        xyz="0 0 0"
        rpy="0 0 0" />
      <geometry>
        <mesh
          filename="../meshes/fr30/visual/shoulder_Link.dae" />
      </geometry>
      <material
        name="">
        <color
          rgba="1 1 1 1" />
      </material>
    </visual>
    <collision>
      <origin
        xyz="0 0 0"
        rpy="0 0 0" />
      <geometry>
        <mesh
          filename="../meshes/fr30/collision/shoulder_Link.STL" />
      </geometry>
    </collision>
  </link>
  <joint
    name="j1"
    type="revolute">
    <origin
      xyz="0 0 0"
      rpy="0 0 0" />
    <parent
      link="base_link" />
    <child
      link="shoulder_Link" />
    <axis
      xyz="0 0 1" />
    <limit
      lower="-3.0543"
      upper="3.0543"
      effort="150"
      velocity="3.15" />
    <calibration
      rising="0"
      falling="0" />
    <dynamics
      damping="0"
      friction="0" />
    <safety_controller
      soft_upper="0"
      soft_lower="0"
      k_position="0"
      k_velocity="0" />
  </joint>
  <link
    name="uppperarm_Link">
    <inertial>
      <origin
        xyz="-0.2914 5.4848E-07 0.22621"
        rpy="0 0 0" />
      <mass
        value="36.37" />
      <inertia
        ixx="0.23721"
        ixy="1.6991E-05"
        ixz="0.00045804"
        iyy="0.75577"
        iyz="-1.666E-06"
        izz="0.72292" />
    </inertial>
    <visual>
      <origin
        xyz="0 0 0"
        rpy="0 0 0" />
      <geometry>
        <mesh
          filename="../meshes/fr30/visual/upperarm_Link.dae" />
      </geometry>
      <material
        name="">
        <color
          rgba="1 1 1 1" />
      </material>
    </visual>
    <collision>
      <origin
        xyz="0 0 0"
        rpy="0 0 0" />
      <geometry>
        <mesh
          filename="../meshes/fr30/collision/upperarm_Link.STL" />
      </geometry>
    </collision>
  </link>
  <joint
    name="j2"
    type="revolute">
    <origin
      xyz="0 0 0.215"
      rpy="1.5708 0 0" />
    <parent
      link="shoulder_Link" />
    <child
      link="uppperarm_Link" />
    <axis
      xyz="0 0 1" />
    <limit
      lower="-4.6251"
      upper="1.4835"
      effort="150"
      velocity="3.15" />
    <calibration
      rising="0"
      falling="0" />
    <dynamics
      damping="0"
      friction="0" />
    <safety_controller
      soft_upper="0"
      soft_lower="0"
      k_position="0"
      k_velocity="0" />
  </joint>
  <link
    name="forearm_Link">
    <inertial>
      <origin
        xyz="-0.23717 -5.0539E-08 0.037483"
        rpy="0 0 0" />
      <mass
        value="8.41" />
      <inertia
        ixx="0.058746"
        ixy="5.8645E-08"
        ixz="-0.0061647"
        iyy="0.18059"
        iyz="-5.4019E-08"
        izz="0.17417" />
    </inertial>
    <visual>
      <origin
        xyz="0 0 0"
        rpy="0 0 0" />
      <geometry>
        <mesh
          filename="../meshes/fr30/visual/forearm_Link.dae" />
      </geometry>
      <material
        name="">
        <color
          rgba="1 1 1 1" />
      </material>
    </visual>
    <collision>
      <origin
        xyz="0 0 0"
        rpy="0 0 0" />
      <geometry>
        <mesh
          filename="../meshes/fr30/collision/forearm_Link.STL" />
      </geometry>
    </collision>
  </link>
  <joint
    name="j3"
    type="revolute">
    <origin
      xyz="-0.7 0 0"
      rpy="0 0 0" />
    <parent
      link="uppperarm_Link" />
    <child
      link="forearm_Link" />
    <axis
      xyz="0 0 1" />
    <limit
      lower="-2.8274"
      upper="2.8274"
      effort="150"
      velocity="3.15" />
    <calibration
      rising="0"
      falling="0" />
    <dynamics
      damping="0"
      friction="0" />
    <safety_controller
      soft_upper="0"
      soft_lower="0"
      k_position="0"
      k_velocity="0" />
  </joint>
  <link
    name="wrist1_Link">
    <inertial>
      <origin
        xyz="-1.3256E-07 -0.0056179 0.16192"
        rpy="0 0 0" />
      <mass
        value="4.64" />
      <inertia
        ixx="0.010725"
        ixy="7.9712E-08"
        ixz="-9.1987E-08"
        iyy="0.0081744"
        iyz="0.0001288"
        izz="0.010402" />
    </inertial>
    <visual>
      <origin
        xyz="0 0 0"
        rpy="0 0 0" />
      <geometry>
        <mesh
          filename="../meshes/fr30/visual/wrist1_Link.dae" />
      </geometry>
      <material
        name="">
        <color
          rgba="1 1 1 1" />
      </material>
    </visual>
    <collision>
      <origin
        xyz="0 0 0"
        rpy="0 0 0" />
      <geometry>
        <mesh
          filename="../meshes/fr30/collision/wrist1_Link.STL" />
      </geometry>
    </collision>
  </link>
  <joint
    name="j4"
    type="revolute">
    <origin
      xyz="-0.536 0 0"
      rpy="0 0 0" />
    <parent
      link="forearm_Link" />
    <child
      link="wrist1_Link" />
    <axis
      xyz="0 0 1" />
    <limit
      lower="-4.6251"
      upper="1.4835"
      effort="28"
      velocity="3.2" />
    <calibration
      rising="0"
      falling="0" />
    <dynamics
      damping="0"
      friction="0" />
    <safety_controller
      soft_upper="0"
      soft_lower="0"
      k_position="0"
      k_velocity="0" />
  </joint>
  <link
    name="wrist2_Link">
    <inertial>
      <origin
        xyz="1.3277E-07 0.0056179 0.13391"
        rpy="0 0 0" />
      <mass
        value="4.64" />
      <inertia
        ixx="0.010725"
        ixy="7.975E-08"
        ixz="9.2016E-08"
        iyy="0.0081744"
        iyz="-0.0001288"
        izz="0.010402" />
    </inertial>
    <visual>
      <origin
        xyz="0 0 0"
        rpy="0 0 0" />
      <geometry>
        <mesh
          filename="../meshes/fr30/visual/wrist2_Link.dae" />
      </geometry>
      <material
        name="">
        <color
          rgba="1 1 1 1" />
      </material>
    </visual>
    <collision>
      <origin
        xyz="0 0 0"
        rpy="0 0 0" />
      <geometry>
        <mesh
          filename="../meshes/fr30/collision/wrist2_Link.STL" />
      </geometry>
    </collision>
  </link>
  <joint
    name="j5"
    type="revolute">
    <origin
      xyz="0 0 0.16601"
      rpy="1.5708 0 0" />
    <parent
      link="wrist1_Link" />
    <child
      link="wrist2_Link" />
    <axis
      xyz="0 0 1" />
    <limit
      lower="-3.0543"
      upper="3.0543"
      effort="28"
      velocity="3.2" />
    <calibration
      rising="0"
      falling="0" />
    <dynamics
      damping="0"
      friction="0" />
    <safety_controller
      soft_upper="0"
      soft_lower="0"
      k_position="0"
      k_velocity="0" />
  </joint>
  <link
    name="wrist3_Link">
    <inertial>
      <origin
        xyz="-0.00011259 -0.00010416 0.095779"
        rpy="0 0 0" />
      <mass
        value="0.6" />
      <inertia
        ixx="0.0010481"
        ixy="3.6643E-10"
        ixz="8.8719E-09"
        iyy="0.0010481"
        iyz="1.6427E-09"
        izz="0.0018226" />
    </inertial>
    <visual>
      <origin
        xyz="0 0 0"
        rpy="0 0 0" />
      <geometry>
        <mesh
          filename="../meshes/fr30/visual/wrist3_Link.dae" />
      </geometry>
      <material
        name="">
        <color
          rgba="1 1 1 1" />
      </material>
    </visual>
    <collision>
      <origin
        xyz="0 0 0"
        rpy="0 0 0" />
      <geometry>
        <mesh
          filename="../meshes/fr30/collision/wrist3_Link.STL" />
      </geometry>
    </collision>
  </link>
  <joint
    name="j6"
    type="revolute">
    <origin
      xyz="0 0 0.138"
      rpy="-1.5708 0 0" />
    <parent
      link="wrist2_Link" />
    <child
      link="wrist3_Link" />
    <axis
      xyz="0 0 1" />
    <limit
      lower="-3.0543"
      upper="3.0543"
      effort="28"
      velocity="3.2" />
    <calibration
      rising="0"
      falling="0" />
    <dynamics
      damping="0"
      friction="0" />
    <safety_controller
      soft_upper="0"
      soft_lower="0"
      k_position="0"
      k_velocity="0" />
  </joint>
  <!-- <link
    name="tool_Link">
    <inertial>
      <origin
        xyz="0.80322 0.11783 -0.15589"
        rpy="0 0 0" />
      <mass
        value="0" />
      <inertia
        ixx="2.0135"
        ixy="0.088625"
        ixz="-0.046535"
        iyy="25.424"
        iyz="-0.16583"
        izz="24.508" />
    </inertial>
    <visual>
      <origin
        xyz="0 0 0"
        rpy="0 0 0" />
      <geometry>
        <mesh
          filename="../tool/tool_Link.dae" />
      </geometry>
      <material
        name="">
        <color
          rgba="1 1 1 1" />
      </material>
    </visual>
    <collision>
      <origin
        xyz="0 0 0"
        rpy="0 0 0" />
      <geometry>
        <mesh
          filename="../tool/tool_Link.STL" />
      </geometry>
    </collision>
  </link> -->
  <joint
    name="tool"
    type="fixed">
    <origin
      xyz="0 0 0.12"
      rpy="0 0 0" />
    <parent
      link="wrist3_Link" />
    <child
      link="tool_Link" />
    <axis
      xyz="0 0 1" />
    <limit
      lower="0"
      upper="0"
      effort="0"
      velocity="0" />
    <calibration
      rising="0"
      falling="0" />
    <dynamics
      damping="0"
      friction="0" />
    <safety_controller
      soft_upper="0"
      soft_lower="0"
      k_position="0"
      k_velocity="0" />
  </joint>
</robot>